Workbook

Sheet 1. Roster & Roles
A1: Roles & Volunteer Roster
A4: Role | B4: Detailed Description & Default Duties | C4: Assigned Leader | D4: Contact Number | E4: Email
A5: Oversight Lead | B5: • Ultimate decision-making authority during the camp. • Handles live issues (emergencies, weather changes). • Leads high-level reflections and debriefs. | C5: Ian Sinclair | D5: +27 63 893 9452 | E5: sinclairian2408@gmail.com
A6: Logistics Lead | B6: • Manages all physical setup and breakdown. • Coordinates camp layout, tents/bivvies, fire preparation. | C6: Neil Harrower | D6: +27 71 950 8363 | E6: neilharrower@gmail.com
A7: Session Coordinator | B7: • Facilitates the core structured spiritual/emotional sessions (e.g., Malachi discussion). | C7: Marvin Welby-Solomon
A8: Communion Leader | B8: • Specifically runs the communion session on Sunday morning. | C8: Richard Walker
A9: Administration | B9: • Handles all paperwork, nametags, and gate-keeping. | C9: Paul Barter
A10: Activity Facilitator | B10: • Brings high energy to run the games and challenges (Clay Latte, Tug of War, Name Games). | C10: Kingsley Williams | D10: +27 83 260 5311
A11: Catering / Food Lead | B11: • Owns the food schedule. Ensures meals are prepped on time. | C11: Kevin de Wet | D11: +27 82 908 2460
A12: General Helper 1 | B12: Assists the Logistics and Catering leads where extra hands are needed. | C12: Raldo Kruger | D12: +27 84 511 8606
A13: General Helper 2 | B13: Assists the Activity Facilitator and Session Coordinator. | C13: Gavin Graham

Sheet 2. Dynamic Timetable
A1: Kickoff Camp Run Sheet
A2: Change the Camp Start Time below. Live tasks will calculate sequentially. Type into "Manual Start Override" to break the chain and set a custom time.
B4: Camp Start Time: | D4: 46053.625
A7: Day | B7: Phase | C7: Manual Start Override | D7: Calculated Start | E7: Calculated End | F7: Duration (min) | G7: Activity Name | H7: Full Task Description | I7: Linked Equipment | J7: Default Role | K7: Custom Override | L7: Final Leader
A8: Saturday | B8: Arrival | D8: =IF(C8<>"", C8, $D$4) -> 0 | E8: =D8 + (F8/1440) -> 0 | F8: 30 | G8: Arrival | H8: Arrive at camp, name tags, get to know contacts | I8: {=IFERROR(JOIN(", ", _xlfn._xlws.FILTER('4. Equipment & Shopping'!B:B, '4. Equipment & Shopping'!D:D=G8)), "None")} -> 0 | J8: Administration | L8: =IF(K8="", IFERROR(VLOOKUP(J8, '1. Roster & Roles'!A:C, 3, FALSE), "Unassigned"), K8) -> 0
A9: Saturday | B9: Ice Breaker | D9: =IF(C9<>"", C9, E8) -> 0 | E9: =D9 + (F9/1440) -> 0 | F9: 30 | G9: Ice Breaker | H9: Get to know each other (Daughters introduce Fathers, name game) | I9: {=IFERROR(JOIN(", ", _xlfn._xlws.FILTER('4. Equipment & Shopping'!B:B, '4. Equipment & Shopping'!D:D=G9)), "None")} -> 0 | J9: Activity Facilitator | L9: =IF(K9="", IFERROR(VLOOKUP(J9, '1. Roster & Roles'!A:C, 3, FALSE), "Unassigned"), K9) -> 0
A10: Saturday | B10: Activity | D10: =IF(C10<>"", C10, E9) -> 0 | E10: =D10 + (F10/1440) -> 0 | F10: 90 | G10: Clay Latte | H10: Father and daughter activities (Clay Latte) & Dam swim | I10: {=IFERROR(JOIN(", ", _xlfn._xlws.FILTER('4. Equipment & Shopping'!B:B, '4. Equipment & Shopping'!D:D=G10)), "None")} -> 0 | J10: Activity Facilitator | L10: =IF(K10="", IFERROR(VLOOKUP(J10, '1. Roster & Roles'!A:C, 3, FALSE), "Unassigned"), K10) -> 0
A11: Saturday | B11: Setup | D11: =IF(C11<>"", C11, E10) -> 0 | E11: =D11 + (F11/1440) -> 0 | F11: 90 | G11: Camp Setup | H11: Set-up shelters, Bivvie equipment, prepare fire | I11: {=IFERROR(JOIN(", ", _xlfn._xlws.FILTER('4. Equipment & Shopping'!B:B, '4. Equipment & Shopping'!D:D=G11)), "None")} -> 0 | J11: Logistics Lead | L11: =IF(K11="", IFERROR(VLOOKUP(J11, '1. Roster & Roles'!A:C, 3, FALSE), "Unassigned"), K11) -> 0
A12: Saturday | B12: Dinner Prep | D12: =IF(C12<>"", C12, E11) -> 0 | E12: =D12 + (F12/1440) -> 0 | F12: 60 | G12: Dinner Prep | H12: Prepare and Cook Supper | I12: {=IFERROR(JOIN(", ", _xlfn._xlws.FILTER('4. Equipment & Shopping'!B:B, '4. Equipment & Shopping'!D:D=G12)), "None")} -> 0 | J12: Catering / Food Lead | L12: =IF(K12="", IFERROR(VLOOKUP(J12, '1. Roster & Roles'!A:C, 3, FALSE), "Unassigned"), K12) -> 0
A13: Saturday | B13: Dinner | D13: =IF(C13<>"", C13, E12) -> 0 | E13: =D13 + (F13/1440) -> 0 | F13: 30 | G13: Dinner | H13: Dads and daughters have supper together | I13: {=IFERROR(JOIN(", ", _xlfn._xlws.FILTER('4. Equipment & Shopping'!B:B, '4. Equipment & Shopping'!D:D=G13)), "None")} -> 0 | J13: Oversight Lead | L13: =IF(K13="", IFERROR(VLOOKUP(J13, '1. Roster & Roles'!A:C, 3, FALSE), "Unassigned"), K13) -> 0
A14: Saturday | B14: Evening | D14: =IF(C14<>"", C14, E13) -> 0 | E14: =D14 + (F14/1440) -> 0 | F14: 60 | G14: Stokbrood | H14: Marshmallows and stokbrood at fire, chat about questions | I14: {=IFERROR(JOIN(", ", _xlfn._xlws.FILTER('4. Equipment & Shopping'!B:B, '4. Equipment & Shopping'!D:D=G14)), "None")} -> 0 | J14: Session Coordinator | L14: =IF(K14="", IFERROR(VLOOKUP(J14, '1. Roster & Roles'!A:C, 3, FALSE), "Unassigned"), K14) -> 0
A15: Saturday | B15: Wind Down | D15: =IF(C15<>"", C15, E14) -> 0 | E15: =D15 + (F15/1440) -> 0 | F15: 60 | G15: Skits & Debrief | H15: Present skits and carving, end of evening debrief | I15: {=IFERROR(JOIN(", ", _xlfn._xlws.FILTER('4. Equipment & Shopping'!B:B, '4. Equipment & Shopping'!D:D=G15)), "None")} -> 0 | J15: Oversight Lead | L15: =IF(K15="", IFERROR(VLOOKUP(J15, '1. Roster & Roles'!A:C, 3, FALSE), "Unassigned"), K15) -> 0
A16: Saturday | B16: Lights Out | D16: =IF(C16<>"", C16, E15) -> 0 | E16: =D16 + (F16/1440) -> 0 | F16: 0 | G16: Bed Time | H16: Bed time | I16: {=IFERROR(JOIN(", ", _xlfn._xlws.FILTER('4. Equipment & Shopping'!B:B, '4. Equipment & Shopping'!D:D=G16)), "None")} -> 0 | J16: Oversight Lead | L16: =IF(K16="", IFERROR(VLOOKUP(J16, '1. Roster & Roles'!A:C, 3, FALSE), "Unassigned"), K16) -> 0
A17: Sunday | B17: Morning | D17: =IF(C17<>"", C17, E16) -> 0 | E17: =D17 + (F17/1440) -> 0 | F17: 45 | G17: Wake Up | H17: Wake up, dam swim, boil kettles, coffee | I17: {=IFERROR(JOIN(", ", _xlfn._xlws.FILTER('4. Equipment & Shopping'!B:B, '4. Equipment & Shopping'!D:D=G17)), "None")} -> 0 | J17: Logistics Lead | L17: =IF(K17="", IFERROR(VLOOKUP(J17, '1. Roster & Roles'!A:C, 3, FALSE), "Unassigned"), K17) -> 0
A18: Sunday | B18: Session 1 | D18: =IF(C18<>"", C18, E17) -> 0 | E18: =D18 + (F18/1440) -> 0 | F18: 90 | G18: Malachi | H18: Malachi discussion (sand demo) and communion | I18: {=IFERROR(JOIN(", ", _xlfn._xlws.FILTER('4. Equipment & Shopping'!B:B, '4. Equipment & Shopping'!D:D=G18)), "None")} -> 0 | J18: Session Coordinator | L18: =IF(K18="", IFERROR(VLOOKUP(J18, '1. Roster & Roles'!A:C, 3, FALSE), "Unassigned"), K18) -> 0
A19: Sunday | B19: Communion | D19: =IF(C19<>"", C19, E18) -> 0 | E19: =D19 + (F19/1440) -> 0 | F19: 30 | G19: Communion | H19: Administer Communion elements | I19: {=IFERROR(JOIN(", ", _xlfn._xlws.FILTER('4. Equipment & Shopping'!B:B, '4. Equipment & Shopping'!D:D=G19)), "None")} -> 0 | J19: Communion Leader | L19: =IF(K19="", IFERROR(VLOOKUP(J19, '1. Roster & Roles'!A:C, 3, FALSE), "Unassigned"), K19) -> 0
A20: Sunday | B20: Session 2 | D20: =IF(C20<>"", C20, E19) -> 0 | E20: =D20 + (F20/1440) -> 0 | F20: 15 | G20: Quiet Time | H20: Father and Daughter Quiet time (reflect on Malachi) | I20: {=IFERROR(JOIN(", ", _xlfn._xlws.FILTER('4. Equipment & Shopping'!B:B, '4. Equipment & Shopping'!D:D=G20)), "None")} -> 0 | J20: Oversight Lead | L20: =IF(K20="", IFERROR(VLOOKUP(J20, '1. Roster & Roles'!A:C, 3, FALSE), "Unassigned"), K20) -> 0
... A26: Sunday | B26: Departure | D26: =IF(C26<>"", C26, E25) -> 0 | E26: =D26 + (F26/1440) -> 0 | F26: 0 | G26: Departure | H26: Depart from camp | I26: {=IFERROR(JOIN(", ", _xlfn._xlws.FILTER('4. Equipment & Shopping'!B:B, '4. Equipment & Shopping'!D:D=G26)), "None")} -> 0 | J26: Administration | L26: =IF(K26="", IFERROR(VLOOKUP(J26, '1. Roster & Roles'!A:C, 3, FALSE), "Unassigned"), K26) -> 0

Sheet 3. Task Checklist
A1: Pre-Camp Task Checklist
A2: Action items and pre-planning organization that need to be completed before arrival.
A5: Category | B5: Task Description | C5: Default Role | D5: Custom Override | E5: Final Assigned | F5: Status
A6: Pre-Planning | B6: Finalize RSVP list and dietary requirements | C6: Administration | E6: =IF(D6="", IFERROR(VLOOKUP(C6, '1. Roster & Roles'!A:C, 3, FALSE), "Unassigned"), D6) -> 0 | F6: Not Started
A7: Pre-Planning | B7: Review medical forms | C7: Oversight Lead | E7: =IF(D7="", IFERROR(VLOOKUP(C7, '1. Roster & Roles'!A:C, 3, FALSE), "Unassigned"), D7) -> 0 | F7: Not Started
A8: Pre-Planning | B8: Purchase all shopping list items (Food/Drinks) | C8: Catering / Food Lead | E8: =IF(D8="", IFERROR(VLOOKUP(C8, '1. Roster & Roles'!A:C, 3, FALSE), "Unassigned"), D8) -> 0 | F8: Not Started
A9: Pre-Planning | B9: Print Name Tags and laminate Father/Daughter questions | C9: Administration | E9: =IF(D9="", IFERROR(VLOOKUP(C9, '1. Roster & Roles'!A:C, 3, FALSE), "Unassigned"), D9) -> 0 | F9: Not Started
A10: Pre-Planning | B10: Confirm venue access codes and final layout | C10: Logistics Lead | E10: =IF(D10="", IFERROR(VLOOKUP(C10, '1. Roster & Roles'!A:C, 3, FALSE), "Unassigned"), D10) -> 0 | F10: Not Started
A11: Pre-Planning | B11: Pack all camp equipment, tents, and activities gear | C11: Logistics Lead | E11: =IF(D11="", IFERROR(VLOOKUP(C11, '1. Roster & Roles'!A:C, 3, FALSE), "Unassigned"), D11) -> 0 | F11: Not Started
A12: Pre-Planning | B12: Pre-pack braai brood and perishables | C12: Catering / Food Lead | E12: =IF(D12="", IFERROR(VLOOKUP(C12, '1. Roster & Roles'!A:C, 3, FALSE), "Unassigned"), D12) -> 0 | F12: Not Started
A13: Pre-Planning | B13: Download YouTube Malachi scripture video | C13: Session Coordinator | E13: =IF(D13="", IFERROR(VLOOKUP(C13, '1. Roster & Roles'!A:C, 3, FALSE), "Unassigned"), D13) -> 0 | F13: Not Started

Sheet 4. Equipment & Shopping
A1: Master Equipment & Shopping List
A5: Category | B5: Item | C5: Qty | D5: Linked Activity | E5: Default Role | F5: Custom Override | G5: Final Assigned | H5: Status
A6: Camp Equipment | B6: Washing bowl | C6: 1 | E6: Logistics Lead | G6: =IF(F6="", IFERROR(VLOOKUP(E6, '1. Roster & Roles'!A:C, 3, FALSE), "Unassigned"), F6) -> 0 | H6: Pending
A7: Camp Equipment | B7: Dish towel | C7: 2 | E7: Logistics Lead | G7: =IF(F7="", IFERROR(VLOOKUP(E7, '1. Roster & Roles'!A:C, 3, FALSE), "Unassigned"), F7) -> 0 | H7: Pending
A8: Camp Equipment | B8: Dish cloth | C8: 5 | E8: Logistics Lead | G8: =IF(F8="", IFERROR(VLOOKUP(E8, '1. Roster & Roles'!A:C, 3, FALSE), "Unassigned"), F8) -> 0 | H8: Pending
A9: Camp Equipment | B9: Dish scourers | C9: 5 | E9: Logistics Lead | G9: =IF(F9="", IFERROR(VLOOKUP(E9, '1. Roster & Roles'!A:C, 3, FALSE), "Unassigned"), F9) -> 0 | H9: Pending
A10: Camp Equipment | B10: Dish washing liquid | C10: 1 | E10: Logistics Lead | G10: =IF(F10="", IFERROR(VLOOKUP(E10, '1. Roster & Roles'!A:C, 3, FALSE), "Unassigned"), F10) -> 0 | H10: Pending
A11: Camp Equipment | B11: Chopping board (wooden) | C11: 4 | E11: Catering / Food Lead | G11: =IF(F11="", IFERROR(VLOOKUP(E11, '1. Roster & Roles'!A:C, 3, FALSE), "Unassigned"), F11) -> 0 | H11: Pending
A12: Camp Equipment | B12: Garbage bags | C12: 5 | E12: Logistics Lead | G12: =IF(F12="", IFERROR(VLOOKUP(E12, '1. Roster & Roles'!A:C, 3, FALSE), "Unassigned"), F12) -> 0 | H12: Pending
A13: Camp Equipment | B13: Spade | C13: 1 | E13: Logistics Lead | G13: =IF(F13="", IFERROR(VLOOKUP(E13, '1. Roster & Roles'!A:C, 3, FALSE), "Unassigned"), F13) -> 0 | H13: Pending
A14: Camp Equipment | B14: Water Carrier | C14: 1 | E14: Logistics Lead | G14: =IF(F14="", IFERROR(VLOOKUP(E14, '1. Roster & Roles'!A:C, 3, FALSE), "Unassigned"), F14) -> 0 | H14: Pending
A15: Camp Equipment | B15: Gas bottles | C15: 2 | E15: Logistics Lead | G15: =IF(F15="", IFERROR(VLOOKUP(E15, '1. Roster & Roles'!A:C, 3, FALSE), "Unassigned"), F15) -> 0 | H15: Pending
A16: Camp Equipment | B16: Gas kettle (Large) | C16: 1 | E16: Logistics Lead | G16: =IF(F16="", IFERROR(VLOOKUP(E16, '1. Roster & Roles'!A:C, 3, FALSE), "Unassigned"), F16) -> 0 | H16: Pending
A17: Camp Equipment | B17: Gas plate | C17: 2 | E17: Logistics Lead | G17: =IF(F17="", IFERROR(VLOOKUP(E17, '1. Roster & Roles'!A:C, 3, FALSE), "Unassigned"), F17) -> 0 | H17: Pending
... A30: Camp Equipment | B30: Mallet | C30: 1 | E30: Logistics Lead | G30: =IF(F30="", IFERROR(VLOOKUP(E30, '1. Roster & Roles'!A:C, 3, FALSE), "Unassigned"), F30) -> 0 | H30: Pending
A31: Camp Equipment | B31: Prop for earth shaking | C31: 1 | D31: Malachi | E31: Session Coordinator | G31: =IF(F31="", IFERROR(VLOOKUP(E31, '1. Roster & Roles'!A:C, 3, FALSE), "Unassigned"), F31) -> 0 | H31: Pending
A32: Camp Equipment | B32: Speaker | C32: 1 | D32: Malachi | E32: Logistics Lead | G32: =IF(F32="", IFERROR(VLOOKUP(E32, '1. Roster & Roles'!A:C, 3, FALSE), "Unassigned"), F32) -> 0 | H32: Pending
A33: Camp Equipment | B33: Projector | C33: 1 | D33: Malachi | E33: Logistics Lead | G33: =IF(F33="", IFERROR(VLOOKUP(E33, '1. Roster & Roles'!A:C, 3, FALSE), "Unassigned"), F33) -> 0 | H33: Pending
A34: Activities | B34: Downloaded YouTube Malachi video | C34: 1 | D34: Malachi | E34: Session Coordinator | G34: =IF(F34="", IFERROR(VLOOKUP(E34, '1. Roster & Roles'!A:C, 3, FALSE), "Unassigned"), F34) -> 0 | H34: Pending
A35: Activities | B35: Dad and daughter questions | C35: 16 | D35: Stokbrood | E35: Session Coordinator | G35: =IF(F35="", IFERROR(VLOOKUP(E35, '1. Roster & Roles'!A:C, 3, FALSE), "Unassigned"), F35) -> 0 | H35: Pending
A36: Activities | B36: Stokbrood Stok | C36: 43 | D36: Stokbrood | E36: Logistics Lead | G36: =IF(F36="", IFERROR(VLOOKUP(E36, '1. Roster & Roles'!A:C, 3, FALSE), "Unassigned"), F36) -> 0 | H36: Pending
A37: Activities | B37: Tug of war rope | C37: 1 | D37: Tug of War | E37: Activity Facilitator | G37: =IF(F37="", IFERROR(VLOOKUP(E37, '1. Roster & Roles'!A:C, 3, FALSE), "Unassigned"), F37) -> 0 | H37: Pending
A38: Activities | B38: Communion cups | C38: 50 | D38: Communion | E38: Communion Leader | G38: =IF(F38="", IFERROR(VLOOKUP(E38, '1. Roster & Roles'!A:C, 3, FALSE), "Unassigned"), F38) -> 0 | H38: Pending
A39: Activities | B39: Claylatt | C39: 43 | D39: Clay Latte | E39: Activity Facilitator | G39: =IF(F39="", IFERROR(VLOOKUP(E39, '1. Roster & Roles'!A:C, 3, FALSE), "Unassigned"), F39) -> 0 | H39: Pending
A40: Activities | B40: Clay - bag | C40: 1 | D40: Clay Latte | E40: Activity Facilitator | G40: =IF(F40="", IFERROR(VLOOKUP(E40, '1. Roster & Roles'!A:C, 3, FALSE), "Unassigned"), F40) -> 0 | H40: Pending
A41: Activities | B41: Bivvy's (Shelter) | C41: 21.5 | D41: Camp Setup | E41: Logistics Lead | G41: =IF(F41="", IFERROR(VLOOKUP(E41, '1. Roster & Roles'!A:C, 3, FALSE), "Unassigned"), F41) -> 0 | H41: Pending
A42: Activities | B42: Latte short (Shelter) | C42: 43 | D42: Camp Setup | E42: Logistics Lead | G42: =IF(F42="", IFERROR(VLOOKUP(E42, '1. Roster & Roles'!A:C, 3, FALSE), "Unassigned"), F42) -> 0 | H42: Pending
... A48: Shopping List (Food) | B48: Coffee Ground | C48: 1 Kg | D48: Wake Up | E48: Catering / Food Lead | G48: =IF(F48="", IFERROR(VLOOKUP(E48, '1. Roster & Roles'!A:C, 3, FALSE), "Unassigned"), F48) -> 0 | H48: Pending
A49: Shopping List (Food) | B49: Long life milk | C49: 12L | E49: Catering / Food Lead | G49: =IF(F49="", IFERROR(VLOOKUP(E49, '1. Roster & Roles'!A:C, 3, FALSE), "Unassigned"), F49) -> 0 | H49: Pending
A50: Shopping List (Food) | B50: Sugar | C50: 1kg | E50: Catering / Food Lead | G50: =IF(F50="", IFERROR(VLOOKUP(E50, '1. Roster & Roles'!A:C, 3, FALSE), "Unassigned"), F50) -> 0 | H50: Pending
A51: Shopping List (Food) | B51: Rusks | C51: 8 boxes | E51: Catering / Food Lead | G51: =IF(F51="", IFERROR(VLOOKUP(E51, '1. Roster & Roles'!A:C, 3, FALSE), "Unassigned"), F51) -> 0 | H51: Pending
A52: Shopping List (Food) | B52: Braai Brood (stok brood) | C52: 6 bags | D52: Stokbrood | E52: Catering / Food Lead | G52: =IF(F52="", IFERROR(VLOOKUP(E52, '1. Roster & Roles'!A:C, 3, FALSE), "Unassigned"), F52) -> 0 | H52: Pending
A53: Shopping List (Food) | B53: Marshmallows | C53: 3 x 300g | D53: Stokbrood | E53: Catering / Food Lead | G53: =IF(F53="", IFERROR(VLOOKUP(E53, '1. Roster & Roles'!A:C, 3, FALSE), "Unassigned"), F53) -> 0 | H53: Pending
A54: Shopping List (Food) | B54: Mieliemeal | C54: 1kg | E54: Catering / Food Lead | G54: =IF(F54="", IFERROR(VLOOKUP(E54, '1. Roster & Roles'!A:C, 3, FALSE), "Unassigned"), F54) -> 0 | H54: Pending
A55: Shopping List (Food) | B55: Rooibos | C55: 1 box | E55: Catering / Food Lead | G55: =IF(F55="", IFERROR(VLOOKUP(E55, '1. Roster & Roles'!A:C, 3, FALSE), "Unassigned"), F55) -> 0 | H55: Pending
A56: Shopping List (Food) | B56: Ceylon | C56: 1 box | E56: Catering / Food Lead | G56: =IF(F56="", IFERROR(VLOOKUP(E56, '1. Roster & Roles'!A:C, 3, FALSE), "Unassigned"), F56) -> 0 | H56: Pending
A57: Shopping List (Food) | B57: Hot chocolate | C57: 1 x 500g | E57: Catering / Food Lead | G57: =IF(F57="", IFERROR(VLOOKUP(E57, '1. Roster & Roles'!A:C, 3, FALSE), "Unassigned"), F57) -> 0 | H57: Pending
A58: Shopping List (Food) | B58: Marie biscuits | C58: 4 pkts | E58: Catering / Food Lead | G58: =IF(F58="", IFERROR(VLOOKUP(E58, '1. Roster & Roles'!A:C, 3, FALSE), "Unassigned"), F58) -> 0 | H58: Pending
A59: Shopping List (Food) | B59: Tomato sauce | C59: 2 bottles | E59: Catering / Food Lead | G59: =IF(F59="", IFERROR(VLOOKUP(E59, '1. Roster & Roles'!A:C, 3, FALSE), "Unassigned"), F59) -> 0 | H59: Pending
A60: Shopping List (Food) | B60: Syrup | C60: 1 x 500g | E60: Catering / Food Lead | G60: =IF(F60="", IFERROR(VLOOKUP(E60, '1. Roster & Roles'!A:C, 3, FALSE), "Unassigned"), F60) -> 0 | H60: Pending
...

Sheet 5. Activity Playbook
A1: Activity Playbook
A2: Detailed rules, concepts, and instructions for each activity.
A5: Linked Activity | B5: Goal / Objective | C5: Instructions & Rules
A6: Clay Latte | B6: Draw fathers and daughters together through teamwork. | C6: Dad and daughter tied together with a guy rope. Must navigate an obstacle course or complete a challenge as a mixed team across the middle line.
A7: Stokbrood | B7: Quality conversational time. | C7: Layout tables, maize meal, dough, stokke, syrup, and marshmallows by the fire. Dads and daughters cook their stokbrood while discussing the printed question cards.
A8: Malachi | B8: Spiritual reflection on restoration. | C8: Show the downloaded YouTube video of the Malachi scripture on the projector/speaker. Demo the shaking sand in a tray. Discuss how the solution is Fathers turning towards children and vice versa.
A9: Communion | B9: Spiritual reflection and partaking. | C9: Administer the communion elements (juice and loaf) together.
A10: Pack Up | B10: Teamwork and responsibility. | C10: Sons/Daughters oversee the packing of their family tent and gear before participating in the final activity.
